Workbook

Sheet Source Report
A1: All Values Use Sample Data | B1: Credit Transaction Detail All Values Use Sample Data
B2: All Values Use Sample Data
A4: All Values Use Sample Data | J4: All Values Use Sample Data
A6: Location ID | B6: DBA Name | C6: Currency Code | D6: Terminal ID | E6: Batch Number | F6: Invoice Number | G6: Submit Date | H6: Card Type | I6: Cardholder Number (Sample Data Using =RandBetween() | J6: Trans Amount | K6: Entry Mode | L6: Entry Desc | M6: Trans Date | N6: Trans Time | O6: Auth Code (Sample Data Using =RandBetween() | P6: Status | Q6: I/C Code | R6: Service Code | S6: Auth Transaction Code | T6: Wallet Identifier | U6: Airline Ticket Number | V6: Transaction Integrity Class
A9: 87625498752 | B9: SampleData.Com | C9: CAD | D9: 0001 | E9: 0240 | F9: 71542033 | G9: 11/02/21 | H9: VISA | I9: 27087******8403 | J9: 31935 | K9: 01 | L9: Manual/key entered (pos 01) | M9: 10/31/21 | N9: 17:42 | O9: 282328D | P9: A | Q9: D33W | R9: UNKNOWN | S9: Unknown Transaction | X9: =IF(D9="0001","3rd Party","") -> 3rd Party
A10: 87625498752 | B10: SampleData.Com | C10: CAD | D10: 0001 | E10: 0240 | F10: 79473840 | G10: 11/02/21 | H10: VISA | I10: 21367******7423 | J10: -20858 | K10: 01 | L10: Manual/key entered (pos 01) | M10: 10/31/21 | N10: 10:36 | O10: 362385D | P10: A | Q10: D33W | R10: UNKNOWN | S10: Unknown Transaction | X10: =IF(D10="0001","3rd Party","") -> 3rd Party
A11: 87625498752 | B11: SampleData.Com | C11: CAD | D11: 0001 | E11: 0240 | F11: 52229374 | G11: 11/02/21 | H11: VISA | I11: 60675******9013 | J11: -11938 | K11: 01 | L11: Manual/key entered (pos 01) | M11: 10/31/21 | N11: 23:33 | O11: 867173D | P11: A | Q11: D33W | R11: UNKNOWN | S11: Unknown Transaction | X11: =IF(D11="0001","3rd Party","") -> 3rd Party
A12: 87625498752 | B12: SampleData.Com | C12: CAD | D12: 0001 | E12: 0240 | F12: 84552782 | G12: 11/02/21 | H12: VISA | I12: 86998******5535 | J12: 25553 | K12: 01 | L12: Manual/key entered (pos 01) | M12: 10/31/21 | N12: 14:48 | O12: 802571D | P12: A | Q12: D33W | R12: UNKNOWN | S12: Unknown Transaction | X12: =IF(D12="0001","3rd Party","") -> 3rd Party
A13: 87625498752 | B13: SampleData.Com | C13: CAD | D13: 0001 | E13: 0240 | F13: 81060210 | G13: 11/02/21 | H13: VISA | I13: 14588******7934 | J13: -19207 | K13: 01 | L13: Manual/key entered (pos 01) | M13: 10/31/21 | N13: 12:18 | O13: 826972D | P13: A | Q13: D33W | R13: UNKNOWN | S13: Unknown Transaction | X13: =IF(D13="0001","3rd Party","") -> 3rd Party
A14: 87625498752 | B14: SampleData.Com | C14: CAD | D14: 0001 | E14: 0240 | F14: 70410573 | G14: 11/02/21 | H14: VISA | I14: 16273******7043 | J14: -27264 | K14: 01 | L14: Manual/key entered (pos 01) | M14: 11/01/21 | N14: 16:26 | O14: 220617D | P14: A | Q14: D33W | R14: UNKNOWN | S14: Unknown Transaction | X14: =IF(D14="0001","3rd Party","") -> 3rd Party
A15: 87625498752 | B15: SampleData.Com | C15: CAD | D15: 0001 | E15: 0240 | F15: 44515910 | G15: 11/02/21 | H15: VISA | I15: 37921******6108 | J15: -37924 | K15: 01 | L15: Manual/key entered (pos 01) | M15: 11/01/21 | N15: 16:16 | O15: 940314D | P15: A | Q15: D33W | R15: UNKNOWN | S15: Unknown Transaction | X15: =IF(D15="0001","3rd Party","") -> 3rd Party
A16: 87625498752 | B16: SampleData.Com | C16: CAD | D16: 0001 | E16: 0240 | F16: 36993672 | G16: 11/02/21 | H16: VISA | I16: 62194******6506 | J16: 23458 | K16: 01 | L16: Manual/key entered (pos 01) | M16: 11/01/21 | N16: 13:58 | O16: 964312D | P16: A | Q16: D33W | R16: UNKNOWN | S16: Unknown Transaction | X16: =IF(D16="0001","3rd Party","") -> 3rd Party
A17: 87625498752 | B17: SampleData.Com | C17: CAD | D17: 0001 | E17: 0240 | F17: 26062449 | G17: 11/02/21 | H17: VISA | I17: 88243******3355 | J17: 32565 | K17: 01 | L17: Manual/key entered (pos 01) | M17: 11/01/21 | N17: 14:27 | O17: 909213D | P17: A | Q17: D33W | R17: UNKNOWN | S17: Unknown Transaction | X17: =IF(D17="0001","3rd Party","") -> 3rd Party
A18: 87625498752 | B18: SampleData.Com | C18: CAD | D18: 0001 | E18: 0240 | F18: 52229127 | G18: 11/02/21 | H18: VISA | I18: 61733******8390 | J18: -41544 | K18: 01 | L18: Manual/key entered (pos 01) | M18: 11/01/21 | N18: 10:50 | O18: 290011D | P18: A | Q18: D33W | R18: UNKNOWN | S18: Unknown Transaction | X18: =IF(D18="0001","3rd Party","") -> 3rd Party
A19: 87625498752 | B19: SampleData.Com | C19: CAD | D19: 0001 | E19: 0240 | F19: 13950935 | G19: 11/02/21 | H19: VISA | I19: 38688******8556 | J19: 49890 | K19: 01 | L19: Manual/key entered (pos 01) | M19: 11/01/21 | N19: 11:38 | O19: 303372D | P19: A | Q19: D33W | R19: UNKNOWN | S19: Unknown Transaction | X19: =IF(D19="0001","3rd Party","") -> 3rd Party
A20: 87625498752 | B20: SampleData.Com | C20: CAD | D20: 0001 | E20: 0240 | F20: 53802084 | G20: 11/02/21 | H20: VISA | I20: 81501******6387 | J20: 14096 | K20: 01 | L20: Manual/key entered (pos 01) | M20: 11/01/21 | N20: 00:24 | O20: 677630D | P20: A | Q20: D33W | R20: UNKNOWN | S20: Unknown Transaction | X20: =IF(D20="0001","3rd Party","") -> 3rd Party
... A27: 87625498752 | B27: SampleData.Com | C27: CAD | D27: 0001 | E27: 0240 | F27: 37870056 | G27: 11/02/21 | H27: VISA | I27: 87598******6998 | J27: -21498 | K27: 01 | L27: Manual/key entered (pos 01) | M27: 11/01/21 | N27: 14:53 | O27: 316215D | P27: A | Q27: D33W | R27: UNKNOWN | S27: Unknown Transaction | X27: =IF(D27="0001","3rd Party","") -> 3rd Party
A28: 87625498752 | B28: SampleData.Com | C28: CAD | D28: 1234 | E28: 0240 | F28: 69728644 | G28: 11/02/21 | H28: VISA | I28: 76447******4714 | J28: -31130 | K28: 01 | L28: Manual/key entered (pos 01) | M28: 11/01/21 | N28: 16:42 | O28: 446386D | P28: A | Q28: D33W | R28: UNKNOWN | S28: Unknown Transaction | X28: =IF(D28="0001","3rd Party","")
A29: 87625498752 | B29: SampleData.Com | C29: CAD | D29: 1234 | E29: 0240 | F29: 70026861 | G29: 11/02/21 | H29: VISA | I29: 52999******4619 | J29: -610 | K29: 01 | L29: Manual/key entered (pos 01) | M29: 11/01/21 | N29: 16:42 | O29: 593287D | P29: A | Q29: D33W | R29: UNKNOWN | S29: Unknown Transaction | X29: =IF(D29="0001","3rd Party","")
A30: 87625498752 | B30: SampleData.Com | C30: CAD | D30: 1234 | E30: 0240 | F30: 69949619 | G30: 11/02/21 | H30: VISA | I30: 65678******1156 | J30: 22483 | K30: 01 | L30: Manual/key entered (pos 01) | M30: 11/01/21 | N30: 10:25 | O30: 251239D | P30: A | Q30: D33W | R30: UNKNOWN | S30: Unknown Transaction | X30: =IF(D30="0001","3rd Party","")
A31: 87625498752 | B31: SampleData.Com | C31: CAD | D31: 1234 | E31: 0240 | F31: 45283529 | G31: 11/02/21 | H31: VISA | I31: 17460******4093 | J31: 31668 | K31: 01 | L31: Manual/key entered (pos 01) | M31: 11/01/21 | N31: 14:10 | O31: 838276D | P31: A | Q31: D33W | R31: UNKNOWN | S31: Unknown Transaction | X31: =IF(D31="0001","3rd Party","")
A32: 87625498752 | B32: SampleData.Com | C32: CAD | D32: 1234 | E32: 0240 | F32: 98635213 | G32: 11/02/21 | H32: VISA | I32: 29322******7642 | J32: -31211 | K32: 01 | L32: Manual/key entered (pos 01) | M32: 11/01/21 | N32: 14:52 | O32: 880284D | P32: A | Q32: D33W | R32: UNKNOWN | S32: Unknown Transaction | X32: =IF(D32="0001","3rd Party","")
A33: 87625498752 | B33: SampleData.Com | C33: CAD | D33: 1234 | E33: 0240 | F33: 41276398 | G33: 11/02/21 | H33: VISA | I33: 56457******7743 | J33: -30173 | K33: 01 | L33: Manual/key entered (pos 01) | M33: 11/01/21 | N33: 12:47 | O33: 918597D | P33: A | Q33: D33W | R33: UNKNOWN | S33: Unknown Transaction | X33: =IF(D33="0001","3rd Party","")
A34: 87625498752 | B34: SampleData.Com | C34: CAD | D34: 1234 | E34: 0240 | F34: 84908480 | G34: 11/02/21 | H34: VISA | I34: 88980******9884 | J34: -8289 | K34: 01 | L34: Manual/key entered (pos 01) | M34: 11/01/21 | N34: 10:59 | O34: 847045D | P34: A | Q34: D33W | R34: UNKNOWN | S34: Unknown Transaction | X34: =IF(D34="0001","3rd Party","")
A35: 87625498752 | B35: SampleData.Com | C35: CAD | D35: 1234 | E35: 0240 | F35: 32329981 | G35: 11/02/21 | H35: VISA | I35: 46600******8003 | J35: 18566 | K35: 01 | L35: Manual/key entered (pos 01) | M35: 11/01/21 | N35: 15:38 | O35: 370296D | P35: A | Q35: D33W | R35: UNKNOWN | S35: Unknown Transaction | X35: =IF(D35="0001","3rd Party","")
A36: 87625498752 | B36: SampleData.Com | C36: CAD | D36: 1234 | E36: 0240 | F36: 51965563 | G36: 11/02/21 | H36: VISA | I36: 81195******4243 | J36: 2917 | K36: 01 | L36: Manual/key entered (pos 01) | M36: 11/01/21 | N36: 15:10 | O36: 439575D | P36: A | Q36: D33W | R36: UNKNOWN | S36: Unknown Transaction | X36: =IF(D36="0001","3rd Party","")
A37: 87625498752 | B37: SampleData.Com | C37: CAD | D37: 1234 | E37: 0240 | F37: 55183558 | G37: 11/02/21 | H37: VISA | I37: 72512******7198 | J37: 12674 | K37: 01 | L37: Manual/key entered (pos 01) | M37: 11/01/21 | N37: 19:20 | O37: 815288D | P37: A | Q37: D33W | R37: UNKNOWN | S37: Unknown Transaction | X37: =IF(D37="0001","3rd Party","")
A38: 87625498752 | B38: SampleData.Com | C38: CAD | D38: 1234 | E38: 0240 | F38: 63418737 | G38: 11/02/21 | H38: VISA | I38: 59909******6340 | J38: -23733 | K38: 01 | L38: Manual/key entered (pos 01) | M38: 11/01/21 | N38: 19:20 | O38: 413556D | P38: A | Q38: D33W | R38: UNKNOWN | S38: Unknown Transaction | X38: =IF(D38="0001","3rd Party","")
A39: 87625498752 | B39: SampleData.Com | C39: CAD | D39: 1234 | E39: 0240 | F39: 93904646 | G39: 11/02/21 | H39: VISA | I39: 87484******8725 | J39: 6382 | K39: 01 | L39: Manual/key entered (pos 01) | M39: 11/01/21 | N39: 16:13 | O39: 515746D | P39: A | Q39: D33W | R39: UNKNOWN | S39: Unknown Transaction | X39: =IF(D39="0001","3rd Party","")
... A173: 87625498752 | B173: SampleData.Com | C173: CAD | D173: 1234 | E173: 0240 | F173: 67117353 | G173: 11/02/21 | H173: MC | I173: 70586******4376 | J173: 23262 | K173: 81 | L173: Electronic commerce transaction | M173: 11/01/21 | N173: 00:00 | O173: 225743D | P173: A | Q173: D33W | R173: UNKNOWN | S173: Unknown Transaction | X173: =IF(D173="0001","3rd Party","")
A174: 87625498752 | B174: SampleData.Com | C174: CAD | D174: 1234 | E174: 0240 | F174: 59588599 | G174: 11/02/21 | H174: MC | I174: 40251******8528 | J174: 11018 | K174: 81 | L174: Electronic commerce transaction | M174: 11/01/21 | N174: 10:25 | O174: 364908D | P174: A | Q174: D33W | R174: UNKNOWN | S174: Unknown Transaction | V174: U0 - Unclassified | X174: =IF(D174="0001","3rd Party","")
A175: 87625498752 | B175: SampleData.Com | C175: CAD | D175: 1234 | E175: 0240 | F175: 88818558 | G175: 11/02/21 | H175: MC | I175: 20357******7647 | J175: 32591 | K175: 81 | L175: Electronic commerce transaction | M175: 10/31/21 | N175: 16:30 | O175: 376826D | P175: A | Q175: D33W | R175: UNKNOWN | S175: Unknown Transaction | X175: =IF(D175="0001","3rd Party","")
A176: 87625498752 | B176: SampleData.Com | C176: CAD | D176: 1234 | E176: 0240 | F176: 50507076 | G176: 11/02/21 | H176: MC | I176: 99468******3406 | J176: -22095 | K176: 81 | L176: Electronic commerce transaction | M176: 10/31/21 | N176: 12:56 | O176: 730838D | P176: A | Q176: D33W | R176: UNKNOWN | S176: Unknown Transaction | X176: =IF(D176="0001","3rd Party","")
A177: 87625498752 | B177: SampleData.Com | C177: CAD | D177: 1234 | E177: 0240 | F177: 85948614 | G177: 11/02/21 | H177: MC | I177: 24873******3142 | J177: -42058 | K177: 81 | L177: Electronic commerce transaction | M177: 11/01/21 | N177: 15:47 | O177: 177466D | P177: A | Q177: D33W | R177: UNKNOWN | S177: Unknown Transaction | X177: =IF(D177="0001","3rd Party","")
A178: 87625498752 | B178: SampleData.Com | C178: CAD | D178: 1234 | E178: 0240 | F178: 87982231 | G178: 11/02/21 | H178: MC | I178: 49392******2329 | J178: -23874 | K178: 81 | L178: Electronic commerce transaction | M178: 11/01/21 | N178: 23:05 | O178: 188501D | P178: A | Q178: D33W | R178: UNKNOWN | S178: Unknown Transaction | X178: =IF(D178="0001","3rd Party","")
A179: 87625498752 | B179: SampleData.Com | C179: CAD | D179: 1234 | E179: 0240 | F179: 12577660 | G179: 11/02/21 | H179: MC | I179: 34584******2327 | J179: -44285 | K179: 81 | L179: Electronic commerce transaction | M179: 11/01/21 | N179: 17:21 | O179: 808421D | P179: A | Q179: D33W | R179: UNKNOWN | S179: Unknown Transaction | X179: =IF(D179="0001","3rd Party","")
A180: 87625498752 | B180: SampleData.Com | C180: CAD | D180: 1234 | E180: 0240 | F180: 94995041 | G180: 11/02/21 | H180: MC | I180: 18146******4395 | J180: -1961 | K180: 81 | L180: Electronic commerce transaction | M180: 11/01/21 | N180: 14:14 | O180: 732124D | P180: A | Q180: D33W | R180: UNKNOWN | S180: Unknown Transaction | X180: =IF(D180="0001","3rd Party","")
A181: 87625498752 | B181: SampleData.Com | C181: CAD | D181: 1234 | E181: 0240 | F181: 16363275 | G181: 11/02/21 | H181: MC | I181: 97034******5678 | J181: -33777 | K181: 81 | L181: Electronic commerce transaction | M181: 11/01/21 | N181: 20:16 | O181: 361648D | P181: A | Q181: D33W | R181: UNKNOWN | S181: Unknown Transaction | X181: =IF(D181="0001","3rd Party","")
A182: 87625498752 | B182: SampleData.Com | C182: CAD | D182: 1234 | E182: 0240 | F182: 91491556 | G182: 11/02/21 | H182: MC | I182: 90265******8295 | J182: -23535 | K182: 81 | L182: Electronic commerce transaction | M182: 11/01/21 | N182: 13:02 | O182: 550196D | P182: A | Q182: D33W | R182: UNKNOWN | S182: Unknown Transaction | X182: =IF(D182="0001","3rd Party","")
A183: 87625498752 | B183: SampleData.Com | C183: CAD | D183: 1234 | E183: 0240 | F183: 30359526 | G183: 11/02/21 | H183: MC | I183: 91409******4817 | J183: 9775 | K183: 81 | L183: Electronic commerce transaction | M183: 11/01/21 | N183: 18:59 | O183: 908972D | P183: A | Q183: D33W | R183: UNKNOWN | S183: Unknown Transaction | X183: =IF(D183="0001","3rd Party","")
...

Sheet Output Dashboard
B2: Amex | G2: Error Check
B3: Credit: | C3: =SUMIFS('Source Report'!$J:$J,'Source Report'!$H:$H,'Output Dashboard'!$B$2,'Source Report'!$J:$J,"<0",'Source Report'!X:X,"<>3rd Party") -> -454595 | D3: =COUNTIFS('Source Report'!H:H,'Output Dashboard'!$B$2,'Source Report'!J:J,"<0",'Source Report'!X:X,"<>3rd Party") -> 21 | G3: Sheet 1 | H3: =SUM('Source Report'!J:J) -> -153522 | I3: =COUNTA('Source Report'!J9:J5000) -> 274
B4: Debit: | C4: =SUMIFS('Source Report'!J:J,'Source Report'!H:H,'Output Dashboard'!$B$2,'Source Report'!J:J,">0",'Source Report'!X:X,"<>3rd Party") -> 588342 | D4: =COUNTIFS('Source Report'!H:H,'Output Dashboard'!$B$2,'Source Report'!J:J,">0",'Source Report'!X:X,"<>3rd Party") -> 21 | G4: Sheet 2 | H4: =SUM(C3:C4,C7:C8,C11:C12,C15:C16,C26:C27) -> -153522 | I4: =SUM(D3:D4,D7:D8,D11:D12,D15:D16,D26:D27) -> 274
G5: Variance | H5: =H3-H4 -> 0 | I5: =I3-I4 -> 0
B6: DSCVR | H6: =H3=H4 -> TRUE | I6: =I3=I4 -> TRUE
B7: Credit: | C7: =SUMIFS('Source Report'!J:J,'Source Report'!H:H,'Output Dashboard'!$B$6,'Source Report'!J:J,"<0",'Source Report'!X:X,"<>3rd Party") -> -30273 | D7: =COUNTIFS('Source Report'!H:H,'Output Dashboard'!$B$6,'Source Report'!J:J,"<0",'Source Report'!X:X,"<>3rd Party") -> 1
B8: Debit: | C8: =SUMIFS('Source Report'!J:J,'Source Report'!H:H,'Output Dashboard'!$B$6,'Source Report'!J:J,">0",'Source Report'!X:X,"<>3rd Party") -> 42198 | D8: =COUNTIFS('Source Report'!H:H,'Output Dashboard'!$B$6,'Source Report'!J:J,">0",'Source Report'!X:X,"<>3rd Party") -> 2
B10: MC
B11: Credit: | C11: =SUMIFS('Source Report'!J:J,'Source Report'!H:H,'Output Dashboard'!$B$10,'Source Report'!J:J,"<0",'Source Report'!X:X,"<>3rd Party") -> -1043775 | D11: =COUNTIFS('Source Report'!H:H,'Output Dashboard'!$B$10,'Source Report'!J:J,"<0",'Source Report'!X:X,"<>3rd Party") -> 40
B12: Debit: | C12: =SUMIFS('Source Report'!J:J,'Source Report'!H:H,'Output Dashboard'!$B$10,'Source Report'!J:J,">0",'Source Report'!X:X,"<>3rd Party") -> 1063626 | D12: =COUNTIFS('Source Report'!H:H,'Output Dashboard'!$B$10,'Source Report'!J:J,">0",'Source Report'!X:X,"<>3rd Party") -> 35
B14: Visa
B15: Credit: | C15: =SUMIFS('Source Report'!J:J,'Source Report'!H:H,'Output Dashboard'!$B$14,'Source Report'!J:J,"<0",'Source Report'!X:X,"<>3rd Party") -> -1851056 | D15: =COUNTIFS('Source Report'!H:H,'Output Dashboard'!$B$14,'Source Report'!J:J,"<0",'Source Report'!X:X,"<>3rd Party") -> 73
B16: Debit: | C16: =SUMIFS('Source Report'!J:J,'Source Report'!H:H,'Output Dashboard'!$B$14,'Source Report'!J:J,">0",'Source Report'!X:X,"<>3rd Party") -> 1491400 | D16: =COUNTIFS('Source Report'!H:H,'Output Dashboard'!$B$14,'Source Report'!J:J,">0",'Source Report'!X:X,"<>3rd Party") -> 62
B18: Visa + MC
B19: Credit: | C19: =C15+C11 -> -2894831 | D19: =D15+D11 -> 113
B20: Debit: | C20: =C16+C12 -> 2555026 | D20: =D16+D12 -> 97
B22: Total
B23: Debit: | C23: =C20+C8+C4 -> 3185566 | D23: =D20+D8+D4 -> 120
B25: 0001
B26: Credit: | C26: =SUMIFS('Source Report'!J:J,'Source Report'!D:D,'Output Dashboard'!$B$25,'Source Report'!J:J,"<0") -> -268131 | D26: =COUNTIFS('Source Report'!D:D,'Output Dashboard'!$B$25,'Source Report'!J:J,"<0") -> 9
B27: Debit: | C27: =SUMIFS('Source Report'!J:J,'Source Report'!D:D,'Output Dashboard'!$B$25,'Source Report'!J:J,">0") -> 308742 | D27: =COUNTIFS('Source Report'!D:D,'Output Dashboard'!$B$25,'Source Report'!J:J,">0") -> 10

Sheet Sheet1
A1: FUCK
